<?xml version="1.0" ?>
<!-- =================================================================================== -->
<!-- |    This document was autogenerated by xacro from workspace/ros_dumpster/src/universal_robot/ur_e_description/urdf/ur10e_joint_limited_robot.urdf.xacro | -->
<!-- |    EDITING THIS FILE BY HAND IS NOT RECOMMENDED                                 | -->
<!-- =================================================================================== -->
<robot name="ur10e">
 <!--
  Author: Kelsey Hawkins
  Contributers: Jimmy Da Silva, Ajit Krisshna N L, Muhammad Asif Rana
-->

  <material name="BlackMat">
    <color rgba="0.03310248 0.03310248 0.03310248 1"/>
  </material>
  <material name="JointGrey">
    <color rgba="0.2784314 0.2784314 0.2784314 1"/>
  </material>
  <material name="URBlue">
    <color rgba="0.4901961 0.6784314 0.8 1"/>
  </material>
  <material name="LinkGrey">
    <color rgba="0.8203922 0.8203922 0.8203922 1"/>
  </material>
  <material name="panda_white">
    <color rgba="0.2784314 0.2784314 0.2784314 1"/>
  </material>

  <link name="base1">
    <visual>
      <geometry>
        <mesh filename="visual/base1.dae"/>
      </geometry>
      <material name="BlackMat"/>
    </visual>
    <inertial>
      <mass value="0.0"/>
      <origin rpy="0 0 0" xyz="0 0 0"/>
      <inertia ixx="0.0" ixy="0.0" ixz="0.0" iyy="0.0" iyz="0.0" izz="0.0"/>
    </inertial>
  </link>
  <joint name="base1-base_link_fixed_joint" type="fixed">
    <parent link="base1"/>
    <child link="base_link"/>
    <origin rpy="0 0 0" xyz="0 0 0"/>
  </joint>
  <link name="base_link">
    <visual>
      <geometry>
        <mesh filename="visual/base2.dae"/>
      </geometry>
      <material name="JointGrey"/>
    </visual>
    <collision>
      <geometry>
        <mesh filename="collision/base.stl"/>
      </geometry>
    </collision>
    <inertial>
      <!-- alper: originally, mass was 4.0 -->
      <mass value="0.0"/> 
      <origin rpy="0 0 0" xyz="0.0 0.0 0.0"/>
      <inertia ixx="0.0061063308908" ixy="0.0" ixz="0.0" iyy="0.0061063308908" iyz="0.0" izz="0.01125"/>
    </inertial>
  </link>
  <joint name="shoulder_pan_joint" type="revolute">
    <parent link="base_link"/>
    <child link="shoulder_link"/>
    <origin rpy="0.0 0.0 0.0" xyz="0.0 0.0 0.181"/>
    <axis xyz="0 0 1"/>
    <limit effort="330.0" lower="-3.141592653589793" upper="3.141592653589793" velocity="3.14"/>
    <dynamics damping="0.0" friction="0.0"/>
  </joint>
  <link name="shoulder_link">
    <visual>
      <geometry>
        <mesh filename="visual/shoulder1.dae"/>
      </geometry>
      <material name="BlackMat"/>
    </visual>
    <collision>
      <geometry>
        <mesh filename="collision/shoulder.stl"/>
      </geometry>
    </collision>
    <inertial>
      <mass value="7.778"/>
      <origin rpy="0 0 0" xyz="0.0 0.0 0.0"/>
      <inertia ixx="0.03147431257693659" ixy="0.0" ixz="0.0" iyy="0.03147431257693659" iyz="0.0" izz="0.021875624999999996"/>
    </inertial>
  </link>
  <joint name="shoulder_link-shoulder2_fixed_joint" type="fixed">
    <parent link="shoulder_link"/>
    <child link="shoulder2"/>
  </joint>
  <link name="shoulder2">
    <visual>
      <geometry>
        <mesh filename="visual/shoulder2.dae"/>
      </geometry>
      <material name="URBlue"/>
    </visual>
    <inertial>
      <mass value="0.0"/>
      <origin rpy="0 0 0" xyz="0.0 0.0 0.0"/>
      <inertia ixx="0.0" ixy="0.0" ixz="0.0" iyy="0.0" iyz="0.0" izz="0.0"/>
    </inertial>
  </link> 
  <joint name="shoulder_link-shoulder3_fixed_joint" type="fixed">
    <parent link="shoulder_link"/>
    <child link="shoulder3"/>
  </joint>
  <link name="shoulder3">
    <visual>
      <geometry>
        <mesh filename="visual/shoulder3.dae"/>
      </geometry>
      <material name="JointGrey"/>
    </visual>
    <inertial>
      <mass value="0.0"/>
      <origin rpy="0 0 0" xyz="0.0 0.0 0.0"/>
      <inertia ixx="0.0" ixy="0.0" ixz="0.0" iyy="0.0" iyz="0.0" izz="0.0"/>
    </inertial>
  </link>
  <joint name="shoulder_lift_joint" type="revolute">
    <parent link="shoulder_link"/>
    <child link="upper_arm_link"/>
    <origin rpy="0.0 1.5707963267948966 0.0" xyz="0.0 0.176 0.0"/>
    <axis xyz="0 1 0"/>
    <limit effort="330.0" lower="-3.141592653589793" upper="3.141592653589793" velocity="3.14"/>
    <dynamics damping="0.0" friction="0.0"/>
  </joint>
  <link name="upper_arm_link">
    <visual>
      <geometry>
        <mesh filename="visual/upperarm1.dae"/>
      </geometry>
      <material name="URBlue"/>
    </visual>
    <collision>
      <geometry>
        <mesh filename="collision/upperarm.stl"/>
      </geometry>
    </collision>
    <inertial>
      <mass value="12.93"/>
      <origin rpy="0 0 0" xyz="0.0 0.0 0.3065"/>
      <inertia ixx="0.4230737407704359" ixy="0.0" ixz="0.0" iyy="0.4230737407704359" iyz="0.0" izz="0.03636562499999999"/>
    </inertial>
  </link>
  <joint name="upper_arm_link-upperarm2_fixed_joint" type="fixed">
    <parent link="upper_arm_link"/>
    <child link="upperarm2"/>
  </joint>
  <link name="upperarm2">
    <visual>
      <geometry>
        <mesh filename="visual/upperarm2.dae"/>
      </geometry>
      <material name="URBlue"/>
    </visual>
    <inertial>
      <mass value="0.0"/>
      <origin rpy="0 0 0" xyz="0.0 0.0 0.0"/>
      <inertia ixx="0.0" ixy="0.0" ixz="0.0" iyy="0.0" iyz="0.0" izz="0.0"/>
    </inertial>
  </link>
  <joint name="upper_arm_link-upperarm3_fixed_joint" type="fixed">
    <parent link="upper_arm_link"/>
    <child link="upperarm3"/>
  </joint>
  <link name="upperarm3">
    <visual>
      <geometry>
        <mesh filename="visual/upperarm3.dae"/>
      </geometry>
      <material name="JointGrey"/>
    </visual>
    <inertial>
      <mass value="0.0"/>
      <origin rpy="0 0 0" xyz="0.0 0.0 0.0"/>
      <inertia ixx="0.0" ixy="0.0" ixz="0.0" iyy="0.0" iyz="0.0" izz="0.0"/>
    </inertial>
  </link>
  <joint name="upper_arm_link-upperarm4_fixed_joint" type="fixed">
    <parent link="upper_arm_link"/>
    <child link="upperarm4"/>
  </joint>
  <link name="upperarm4">
    <visual>
      <geometry>
        <mesh filename="visual/upperarm4.dae"/>
      </geometry>
      <material name="BlackMat"/>
    </visual>
    <inertial>
      <mass value="0.0"/>
      <origin rpy="0 0 0" xyz="0.0 0.0 0.0"/>
      <inertia ixx="0.0" ixy="0.0" ixz="0.0" iyy="0.0" iyz="0.0" izz="0.0"/>
    </inertial>
  </link>
  <joint name="upper_arm_link-upperarm5_fixed_joint" type="fixed">
    <parent link="upper_arm_link"/>
    <child link="upperarm5"/>
  </joint>
  <link name="upperarm5">
    <visual>
      <geometry>
        <mesh filename="visual/upperarm5.dae"/>
      </geometry>
      <material name="JointGrey"/>
    </visual>
    <inertial>
      <mass value="0.0"/>
      <origin rpy="0 0 0" xyz="0.0 0.0 0.0"/>
      <inertia ixx="0.0" ixy="0.0" ixz="0.0" iyy="0.0" iyz="0.0" izz="0.0"/>
    </inertial>
  </link>
  <joint name="upper_arm_link-upperarm6_fixed_joint" type="fixed">
    <parent link="upper_arm_link"/>
    <child link="upperarm6"/>
  </joint>
  <link name="upperarm6">
    <visual>
      <geometry>
        <mesh filename="visual/upperarm6.dae"/>
      </geometry>
      <material name="BlackMat"/>
    </visual>
    <inertial>
      <mass value="0.0"/>
      <origin rpy="0 0 0" xyz="0.0 0.0 0.0"/>
      <inertia ixx="0.0" ixy="0.0" ixz="0.0" iyy="0.0" iyz="0.0" izz="0.0"/>
    </inertial>
  </link>
  <joint name="upper_arm_link-upperarm7_fixed_joint" type="fixed">
    <parent link="upper_arm_link"/>
    <child link="upperarm7"/>
  </joint>
  <link name="upperarm7">
    <visual>
      <geometry>
        <mesh filename="visual/upperarm7.dae"/>
      </geometry>
      <material name="BlackMat"/>
    </visual>
    <inertial>
      <mass value="0.0"/>
      <origin rpy="0 0 0" xyz="0.0 0.0 0.0"/>
      <inertia ixx="0.0" ixy="0.0" ixz="0.0" iyy="0.0" iyz="0.0" izz="0.0"/>
    </inertial>
  </link>
  <joint name="upper_arm_link-upperarm8_fixed_joint" type="fixed">
    <parent link="upper_arm_link"/>
    <child link="upperarm8"/>
  </joint>
  <link name="upperarm8">
    <visual>
      <geometry>
        <mesh filename="visual/upperarm8.dae"/>
      </geometry>
      <material name="LinkGrey"/>
    </visual>
    <inertial>
      <mass value="0.0"/>
      <origin rpy="0 0 0" xyz="0.0 0.0 0.0"/>
      <inertia ixx="0.0" ixy="0.0" ixz="0.0" iyy="0.0" iyz="0.0" izz="0.0"/>
    </inertial>
  </link>
  <joint name="elbow_joint" type="revolute">
    <parent link="upper_arm_link"/>
    <child link="forearm_link"/>
    <origin rpy="0.0 0.0 0.0" xyz="0.0 -0.137 0.613"/>
    <axis xyz="0 1 0"/>
    <limit effort="150.0" lower="-3.141592653589793" upper="3.141592653589793" velocity="3.14"/>
    <dynamics damping="0.0" friction="0.0"/>
  </joint>
  <link name="forearm_link">
    <visual>
      <geometry>
        <mesh filename="visual/forearm1.dae"/>
      </geometry>
      <material name="JointGrey"/>
    </visual>
    <collision>
      <geometry>
        <mesh filename="collision/forearm.stl"/>
      </geometry>
    </collision>
    <inertial>
      <mass value="3.87"/>
      <origin rpy="0 0 0" xyz="0.0 0.0 0.2855"/>
      <inertia ixx="0.11059036576383598" ixy="0.0" ixz="0.0" iyy="0.11059036576383598" iyz="0.0" izz="0.010884375"/>
    </inertial>
  </link>
  <joint name="forearm_link-forearm2_fixed_joint" type="fixed">
    <parent link="forearm_link"/>
    <child link="forearm2"/>
  </joint>
  <link name="forearm2">
    <visual>
      <geometry>
        <mesh filename="visual/forearm2.dae"/>
      </geometry>
      <material name="BlackMat"/>
    </visual>
    <inertial>
      <mass value="0.0"/>
      <origin rpy="0 0 0" xyz="0.0 0.0 0.0"/>
      <inertia ixx="0.0" ixy="0.0" ixz="0.0" iyy="0.0" iyz="0.0" izz="0.0"/>
    </inertial>
  </link>
  <joint name="forearm_link-forearm3_fixed_joint" type="fixed">
    <parent link="forearm_link"/>
    <child link="forearm3"/>
  </joint>
  <link name="forearm3">
    <visual>
      <geometry>
        <mesh filename="visual/forearm3.dae"/>
      </geometry>
      <material name="URBlue"/>
    </visual>
    <inertial>
      <mass value="0.0"/>
      <origin rpy="0 0 0" xyz="0.0 0.0 0.0"/>
      <inertia ixx="0.0" ixy="0.0" ixz="0.0" iyy="0.0" iyz="0.0" izz="0.0"/>
    </inertial>
  </link>
  <joint name="forearm_link-forearm4_fixed_joint" type="fixed">
    <parent link="forearm_link"/>
    <child link="forearm4"/>
  </joint>
  <link name="forearm4">
    <visual>
      <geometry>
        <mesh filename="visual/forearm4.dae"/>
      </geometry>
      <material name="JointGrey"/>
    </visual>
    <inertial>
      <mass value="0.0"/>
      <origin rpy="0 0 0" xyz="0.0 0.0 0.0"/>
      <inertia ixx="0.0" ixy="0.0" ixz="0.0" iyy="0.0" iyz="0.0" izz="0.0"/>
    </inertial>
  </link>
  <joint name="forearm_link-forearm5_fixed_joint" type="fixed">
    <parent link="forearm_link"/>
    <child link="forearm5"/>
  </joint>
  <link name="forearm5">
    <visual>
      <geometry>
        <mesh filename="visual/forearm5.dae"/>
      </geometry>
      <material name="BlackMat"/>
    </visual>
    <inertial>
      <mass value="0.0"/>
      <origin rpy="0 0 0" xyz="0.0 0.0 0.0"/>
      <inertia ixx="0.0" ixy="0.0" ixz="0.0" iyy="0.0" iyz="0.0" izz="0.0"/>
    </inertial>
  </link>
  <joint name="forearm_link-forearm6_fixed_joint" type="fixed">
    <parent link="forearm_link"/>
    <child link="forearm6"/>
  </joint>
  <link name="forearm6">
    <visual>
      <geometry>
        <mesh filename="visual/forearm6.dae"/>
      </geometry>
      <material name="BlackMat"/>
    </visual>
    <inertial>
      <mass value="0.0"/>
      <origin rpy="0 0 0" xyz="0.0 0.0 0.0"/>
      <inertia ixx="0.0" ixy="0.0" ixz="0.0" iyy="0.0" iyz="0.0" izz="0.0"/>
    </inertial>
  </link>
  <joint name="forearm_link-forearm7_fixed_joint" type="fixed">
    <parent link="forearm_link"/>
    <child link="forearm7"/>
  </joint>
  <link name="forearm7">
    <visual>
      <geometry>
        <mesh filename="visual/forearm7.dae"/>
      </geometry>
      <material name="LinkGrey"/>
    </visual>
    <inertial>
      <mass value="0.0"/>
      <origin rpy="0 0 0" xyz="0.0 0.0 0.0"/>
      <inertia ixx="0.0" ixy="0.0" ixz="0.0" iyy="0.0" iyz="0.0" izz="0.0"/>
    </inertial>
  </link>
  <joint name="wrist_1_joint" type="revolute">
    <parent link="forearm_link"/>
    <child link="wrist_1_link"/>
    <origin rpy="0.0 1.5707963267948966 0.0" xyz="0.0 0.0 0.571"/>
    <axis xyz="0 1 0"/>
    <limit effort="54.0" lower="-3.141592653589793" upper="3.141592653589793" velocity="6.28"/>
    <dynamics damping="0.0" friction="0.0"/>
  </joint>
  <link name="wrist_1_link">
    <visual>
      <geometry>
        <mesh filename="visual/wrist1_1.dae"/>
      </geometry>
      <material name="URBlue"/>
    </visual>
    <collision>
      <geometry>
        <mesh filename="collision/wrist1.stl"/>
      </geometry>
    </collision>
    <inertial>
      <mass value="1.96"/>
      <origin rpy="0 0 0" xyz="0.0 0.135 0.0"/>
      <inertia ixx="0.005108247956699999" ixy="0.0" ixz="0.0" iyy="0.005108247956699999" iyz="0.0" izz="0.005512499999999999"/>
    </inertial>
  </link>
  <joint name="wrist_1_link-wrist_1_2_fixed_joint" type="fixed">
    <parent link="wrist_1_link"/>
    <child link="wrist_1_2"/>
  </joint>
  <link name="wrist_1_2">
    <visual>
      <geometry>
        <mesh filename="visual/wrist1_2.dae"/>
      </geometry>
      <material name="BlackMat"/>
    </visual>
    <inertial>
      <mass value="0.0"/>
      <origin rpy="0 0 0" xyz="0.0 0.0 0"/>
      <inertia ixx="0.0" ixy="0.0" ixz="0.0" iyy="0.0" iyz="0.0" izz="0.0"/>
    </inertial>
  </link>
  <joint name="wrist_1_link-wrist_1_3_fixed_joint" type="fixed">
    <parent link="wrist_1_link"/>
    <child link="wrist_1_3"/>
  </joint>
  <link name="wrist_1_3">
    <visual>
      <geometry>
        <mesh filename="visual/wrist1_3.dae"/>
      </geometry>
      <material name="JointGrey"/>
    </visual>
    <inertial>
      <mass value="0.0"/>
      <origin rpy="0 0 0" xyz="0.0 0.0 0"/>
      <inertia ixx="0.0" ixy="0.0" ixz="0.0" iyy="0.0" iyz="0.0" izz="0.0"/>
    </inertial>
  </link>
  <joint name="wrist_2_joint" type="revolute">
    <parent link="wrist_1_link"/>
    <child link="wrist_2_link"/>
    <origin rpy="0.0 0.0 0.0" xyz="0.0 0.135 0.0"/>
    <axis xyz="0 0 1"/>
    <limit effort="54.0" lower="-3.141592653589793" upper="3.141592653589793" velocity="6.28"/>
    <dynamics damping="0.0" friction="0.0"/>
  </joint>
  <link name="wrist_2_link">
    <visual>
      <geometry>
        <mesh filename="visual/wrist2_1.dae"/>
      </geometry>
      <material name="URBlue"/>
    </visual>
    <collision>
      <geometry>
        <mesh filename="collision/wrist2.stl"/>
      </geometry>
    </collision>
    <inertial>
      <mass value="1.96"/>
      <origin rpy="0 0 0" xyz="0.0 0.0 0.12"/>
      <inertia ixx="0.005108247956699999" ixy="0.0" ixz="0.0" iyy="0.005108247956699999" iyz="0.0" izz="0.005512499999999999"/>
    </inertial>
  </link>
  <joint name="wrist_2_link-wrist_2_2_fixed_joint" type="fixed">
    <parent link="wrist_2_link"/>
    <child link="wrist_2_2"/>
  </joint>
  <link name="wrist_2_2">
    <visual>
      <geometry>
        <mesh filename="visual/wrist2_2.dae"/>
      </geometry>
      <material name="BlackMat"/>
    </visual>
    <inertial>
      <mass value="0.0"/>
      <origin rpy="0 0 0" xyz="0.0 0.0 0"/>
      <inertia ixx="0.0" ixy="0.0" ixz="0.0" iyy="0.0" iyz="0.0" izz="0.0"/>
    </inertial>
  </link>
  <joint name="wrist_2_link-wrist_2_3_fixed_joint" type="fixed">
    <parent link="wrist_2_link"/>
    <child link="wrist_2_3"/>
  </joint>
  <link name="wrist_2_3">
    <visual>
      <geometry>
        <mesh filename="visual/wrist2_3.dae"/>
      </geometry>
      <material name="JointGrey"/>
    </visual>
    <inertial>
      <mass value="0.0"/>
      <origin rpy="0 0 0" xyz="0.0 0.0 0"/>
      <inertia ixx="0.0" ixy="0.0" ixz="0.0" iyy="0.0" iyz="0.0" izz="0.0"/>
    </inertial>
  </link>
  <joint name="wrist_3_joint" type="revolute">
    <parent link="wrist_2_link"/>
    <child link="wrist_3_link"/>
    <origin rpy="0.0 0.0 0.0" xyz="0.0 0.0 0.12"/>
    <axis xyz="0 1 0"/>
    <limit effort="54.0" lower="-3.141592653589793" upper="3.141592653589793" velocity="6.28"/>
    <dynamics damping="0.0" friction="0.0"/>
  </joint>
  <link name="wrist_3_link">
    <visual>
      <geometry>
        <mesh filename="visual/wrist3.dae"/>
      </geometry>
      <material name="LinkGrey"/>
    </visual>
    <collision>
      <geometry>
        <mesh filename="collision/wrist3.stl"/>
      </geometry>
    </collision>
    <inertial>
      <mass value="0.202"/>
      <origin rpy="1.5707963267948966 0 0" xyz="0.0 0.092 0.0"/>
      <inertia ixx="0.04434577559500002" ixy="0.0" ixz="0.0" iyy="0.04434577559500002" iyz="0.0" izz="0.00020452500000000002"/>
    </inertial>
  </link>

  <link name="tool0">
    <!-- alper: I added inertial -->
    <inertial>
      <mass value="0.0"/>
      <origin rpy="0 0 0" xyz="0.0 0.0 0.0"/>
      <inertia ixx="0.0" ixy="0.0" ixz="0.0" iyy="0.0" iyz="0.0" izz="0.0"/>
    </inertial>
  </link>
<!-- -1.5707963267948966 -->
  <joint name="wrist_3_link-tool0_fixed_joint" type="fixed">
    <origin rpy="0 3.141592653589793 0" xyz="0 0.117 0"/>
    <parent link="wrist_3_link"/>
    <child link="tool0"/>
  </joint>

  <joint name="panda_hand_joint" type="fixed">
    <parent link="tool0"/>
    <child link="panda_hand"/>
    <origin rpy="-1.57 0 0" xyz="0 0 0"/>
  </joint>

  <link name="panda_hand">
    <inertial>
      <origin rpy="0 0 0" xyz="0 0 0.04"/>
       <mass value=".81"/>
       <inertia ixx="0.1" ixy="0" ixz="0" iyy="0.1" iyz="0" izz="0.1"/>
    </inertial>
    <visual>
      <geometry>
        <mesh filename="package://visual/hand.obj"/>
      </geometry>
      <material name="panda_white"/>
    </visual>
    <collision>
      <geometry>
        <mesh filename="package://collision/hand.obj"/>
      </geometry>
      <material name="panda_white"/>
    </collision>
  </link>
  <link name="panda_leftfinger">
    <contact>
      <friction_anchor/>
      <stiffness value="30000.0"/>
      <damping value="1000.0"/>
      <spinning_friction value="0.1"/>
      <lateral_friction value="1.0"/>
    </contact>
    <inertial>
      <origin rpy="0 0 0" xyz="0 0.01 0.02"/>
       <mass value="0.1"/>
       <inertia ixx="0.1" ixy="0" ixz="0" iyy="0.1" iyz="0" izz="0.1"/>
    </inertial>
    <visual>
      <geometry>
        <mesh filename="package://visual/finger.obj"/>
      </geometry>
      <material name="panda_white"/>
    </visual>
    <collision>
      <geometry>
        <mesh filename="package://collision/finger.obj"/>
      </geometry>
      <material name="panda_white"/>
    </collision>
  </link>
  <link name="panda_rightfinger">
    <contact>
      <friction_anchor/>
      <stiffness value="30000.0"/>
      <damping value="1000.0"/>
      <spinning_friction value="0.1"/>
      <lateral_friction value="1.0"/>
    </contact>
    <inertial>
      <origin rpy="0 0 0" xyz="0 -0.01 0.02"/>
       <mass value="0.1"/>
       <inertia ixx="0.1" ixy="0" ixz="0" iyy="0.1" iyz="0" izz="0.1"/>
    </inertial>
    <visual>
      <origin rpy="0 0 3.14159265359" xyz="0 0 0"/>
      <geometry>
        <mesh filename="package://visual/finger.obj"/>
      </geometry>
      <material name="panda_white"/>
    </visual>
    <collision>
      <origin rpy="0 0 3.14159265359" xyz="0 0 0"/>
      <geometry>
        <mesh filename="package://collision/finger.obj"/>
      </geometry>
      <material name="panda_white"/>
    </collision>
  </link>
  <joint name="panda_finger_joint1" type="prismatic">
    <parent link="panda_hand"/>
    <child link="panda_leftfinger"/>
    <origin rpy="0 0 0" xyz="0 0 0.0584"/>
    <axis xyz="0 1 0"/>
    <limit effort="20" lower="0.0" upper="0.04" velocity="0.2"/>
  </joint>
  <joint name="panda_finger_joint2" type="prismatic">
    <parent link="panda_hand"/>
    <child link="panda_rightfinger"/>
    <origin rpy="0 0 0" xyz="0 0 0.0584"/>
    <axis xyz="0 -1 0"/>
    <limit effort="20" lower="0.0" upper="0.04" velocity="0.2"/>
    <mimic joint="panda_finger_joint1"/>
  </joint>
  <link name="panda_grasptarget">
    <inertial>
      <origin rpy="0 0 0" xyz="0 0 0"/>
       <mass value="0.0"/>
       <inertia ixx="0.1" ixy="0" ixz="0" iyy="0.1" iyz="0" izz="0.1"/>
    </inertial>
  </link>
  <joint name="panda_grasptarget_hand" type="fixed">
    <parent link="panda_hand"/>
    <child link="panda_grasptarget"/>
    <origin rpy="0 0 0" xyz="0 0 0.105"/>
  </joint>
</robot>
